Traceback (most recent call last):
  File "C:\Users\Anna\AppData\Local\Programs\Python\Python39\lib\site-packages\jupyter_cache\executors\utils.py", line 51, in single_nb_execution
    executenb(
  File "C:\Users\Anna\AppData\Local\Programs\Python\Python39\lib\site-packages\nbclient\client.py", line 1204, in execute
    return NotebookClient(nb=nb, resources=resources, km=km, **kwargs).execute()
  File "C:\Users\Anna\AppData\Local\Programs\Python\Python39\lib\site-packages\nbclient\util.py", line 84, in wrapped
    return just_run(coro(*args, **kwargs))
  File "C:\Users\Anna\AppData\Local\Programs\Python\Python39\lib\site-packages\nbclient\util.py", line 62, in just_run
    return loop.run_until_complete(coro)
  File "C:\Users\Anna\AppData\Local\Programs\Python\Python39\lib\asyncio\base_events.py", line 647, in run_until_complete
    return future.result()
  File "C:\Users\Anna\AppData\Local\Programs\Python\Python39\lib\site-packages\nbclient\client.py", line 663, in async_execute
    await self.async_execute_cell(
  File "C:\Users\Anna\AppData\Local\Programs\Python\Python39\lib\site-packages\nbclient\client.py", line 965, in async_execute_cell
    await self._check_raise_for_error(cell, cell_index, exec_reply)
  File "C:\Users\Anna\AppData\Local\Programs\Python\Python39\lib\site-packages\nbclient\client.py", line 862, in _check_raise_for_error
    raise CellExecutionError.from_cell_and_msg(cell, exec_reply_content)
nbclient.exceptions.CellExecutionError: An error occurred while executing the following cell:
------------------
#train_loss_multipos = model_multipos.train(train_loader, n_epochs=EPOCHS, learning=learning_rate)

xAx = [i for i in range(1, EPOCHS+1)]
plt.plot(xAx, train_loss_multipos)
plt.xlabel("Epoch")
plt.ylabel("Cross Entropy Loss")
plt.xlim(0, EPOCHS)
plt.xticks([j*20 for j in range(EPOCHS // 20 + 1)])
plt.title("Training Loss")
plt.show()
------------------

[1;31m---------------------------------------------------------------------------[0m
[1;31mNameError[0m                                 Traceback (most recent call last)
Input [1;32mIn [9][0m, in [0;36m<cell line: 4>[1;34m()[0m
[0;32m      1[0m [38;5;66;03m#train_loss_multipos = model_multipos.train(train_loader, n_epochs=EPOCHS, learning=learning_rate)[39;00m
[0;32m      3[0m xAx [38;5;241m=[39m [i [38;5;28;01mfor[39;00m i [38;5;129;01min[39;00m [38;5;28mrange[39m([38;5;241m1[39m, EPOCHS[38;5;241m+[39m[38;5;241m1[39m)]
[1;32m----> 4[0m plt[38;5;241m.[39mplot(xAx, [43mtrain_loss_multipos[49m)
[0;32m      5[0m plt[38;5;241m.[39mxlabel([38;5;124m"[39m[38;5;124mEpoch[39m[38;5;124m"[39m)
[0;32m      6[0m plt[38;5;241m.[39mylabel([38;5;124m"[39m[38;5;124mCross Entropy Loss[39m[38;5;124m"[39m)

[1;31mNameError[0m: name 'train_loss_multipos' is not defined
NameError: name 'train_loss_multipos' is not defined

